# SOME DESCRIPTIVE TITLE.
# Copyright (C) 2001-2025, Python Software Foundation
# This file is distributed under the same license as the Python package.
# FIRST AUTHOR <EMAIL@ADDRESS>, YEAR.
#
# Translators:
# Rafael Fontenelle <rffontenelle@gmail.com>, 2024
#
#, fuzzy
msgid ""
msgstr ""
"Project-Id-Version: Python 3.11\n"
"Report-Msgid-Bugs-To: \n"
"POT-Creation-Date: 2025-01-03 15:28+0000\n"
"PO-Revision-Date: 2023-05-24 02:12+0000\n"
"Last-Translator: Rafael Fontenelle <rffontenelle@gmail.com>, 2024\n"
"Language-Team: Russian (https://app.transifex.com/python-doc/teams/5390/"
"ru/)\n"
"MIME-Version: 1.0\n"
"Content-Type: text/plain; charset=UTF-8\n"
"Content-Transfer-Encoding: 8bit\n"
"Language: ru\n"
"Plural-Forms: nplurals=4; plural=(n%10==1 && n%100!=11 ? 0 : n%10>=2 && "
"n%10<=4 && (n%100<12 || n%100>14) ? 1 : n%10==0 || (n%10>=5 && n%10<=9) || "
"(n%100>=11 && n%100<=14)? 2 : 3);\n"

#: ../../library/asyncio-exceptions.rst:8
msgid "Exceptions"
msgstr "Исключения"

#: ../../library/asyncio-exceptions.rst:10
msgid "**Source code:** :source:`Lib/asyncio/exceptions.py`"
msgstr "**Исходный код:** :source:`Lib/asyncio/exceptions.py`"

#: ../../library/asyncio-exceptions.rst:16
msgid ""
"A deprecated alias of :exc:`TimeoutError`, raised when the operation has "
"exceeded the given deadline."
msgstr ""
"Устаревший псевдоним :exc:`TimeoutError`, вызываемый, когда операция "
"превысила заданный крайний срок."

#: ../../library/asyncio-exceptions.rst:21
msgid "This class was made an alias of :exc:`TimeoutError`."
msgstr "Этот класс стал псевдонимом :exc:`TimeoutError`."

#: ../../library/asyncio-exceptions.rst:26
msgid "The operation has been cancelled."
msgstr "Операция отменена."

#: ../../library/asyncio-exceptions.rst:28
msgid ""
"This exception can be caught to perform custom operations when asyncio Tasks "
"are cancelled.  In almost all situations the exception must be re-raised."
msgstr ""
"Это исключение можно перехватить для выполнения пользовательских операций "
"при отмене задач asyncio. Почти во всех ситуациях исключение необходимо "
"вызвать повторно."

#: ../../library/asyncio-exceptions.rst:34
msgid ""
":exc:`CancelledError` is now a subclass of :class:`BaseException` rather "
"than :class:`Exception`."
msgstr ""
":exc:`CancelledError` теперь является подклассом :class:`BaseException`, а "
"не :class:`Exception`."

#: ../../library/asyncio-exceptions.rst:39
msgid "Invalid internal state of :class:`Task` or :class:`Future`."
msgstr "Недопустимое внутреннее состояние :class:`Task` или :class:`Future`."

#: ../../library/asyncio-exceptions.rst:41
msgid ""
"Can be raised in situations like setting a result value for a *Future* "
"object that already has a result value set."
msgstr ""
"Может вызываться в таких ситуациях, как установка результирующего значения "
"для объекта *Future*, для которого уже установлено результирующее значение."

#: ../../library/asyncio-exceptions.rst:47
msgid ""
"The \"sendfile\" syscall is not available for the given socket or file type."
msgstr "Системный вызов sendfile недоступен для данного сокета или типа файла."

#: ../../library/asyncio-exceptions.rst:50
msgid "A subclass of :exc:`RuntimeError`."
msgstr "Подкласс :exc:`RuntimeError`."

#: ../../library/asyncio-exceptions.rst:55
msgid "The requested read operation did not complete fully."
msgstr "Запрошенная операция чтения не завершена полностью."

#: ../../library/asyncio-exceptions.rst:57
msgid "Raised by the :ref:`asyncio stream APIs<asyncio-streams>`."
msgstr "Вызывается :ref:`API потока asyncio<asyncio-streams>`."

#: ../../library/asyncio-exceptions.rst:59
msgid "This exception is a subclass of :exc:`EOFError`."
msgstr "Это исключение является подклассом :exc:`EOFError`."

#: ../../library/asyncio-exceptions.rst:63
msgid "The total number (:class:`int`) of expected bytes."
msgstr "Общее количество (:class:`int`) ожидаемых байтов."

#: ../../library/asyncio-exceptions.rst:67
msgid "A string of :class:`bytes` read before the end of stream was reached."
msgstr "Строка :class:`bytes`, прочитанная до достижения конца потока."

#: ../../library/asyncio-exceptions.rst:72
msgid "Reached the buffer size limit while looking for a separator."
msgstr "Достигнут предел размера буфера при поиске разделителя."

#: ../../library/asyncio-exceptions.rst:74
msgid "Raised by the :ref:`asyncio stream APIs <asyncio-streams>`."
msgstr "Вызывается :ref:`API потока asyncio <asyncio-streams>`."

#: ../../library/asyncio-exceptions.rst:78
msgid "The total number of to be consumed bytes."
msgstr "Общее количество потребляемых байт."
